Traceback (most recent call last):
  File "C:\Users\aviav\AppData\Local\Programs\Python\Python311\Lib\site-packages\jupyter_cache\executors\utils.py", line 58, in single_nb_execution
    executenb(
  File "C:\Users\aviav\AppData\Local\Programs\Python\Python311\Lib\site-packages\nbclient\client.py", line 1319, in execute
    return NotebookClient(nb=nb, resources=resources, km=km, **kwargs).execute()
           ^^^^^^^^^^^^^^^^^^^^^^^^^^^^^^^^^^^^^^^^^^^^^^^^^^^^^^^^^^^^^^^^^^^^^
  File "C:\Users\aviav\AppData\Local\Programs\Python\Python311\Lib\site-packages\jupyter_core\utils\__init__.py", line 165, in wrapped
    return loop.run_until_complete(inner)
           ^^^^^^^^^^^^^^^^^^^^^^^^^^^^^^
  File "C:\Users\aviav\AppData\Local\Programs\Python\Python311\Lib\asyncio\base_events.py", line 654, in run_until_complete
    return future.result()
           ^^^^^^^^^^^^^^^
  File "C:\Users\aviav\AppData\Local\Programs\Python\Python311\Lib\site-packages\nbclient\client.py", line 709, in async_execute
    await self.async_execute_cell(
  File "C:\Users\aviav\AppData\Local\Programs\Python\Python311\Lib\site-packages\nbclient\client.py", line 1062, in async_execute_cell
    await self._check_raise_for_error(cell, cell_index, exec_reply)
  File "C:\Users\aviav\AppData\Local\Programs\Python\Python311\Lib\site-packages\nbclient\client.py", line 918, in _check_raise_for_error
    raise CellExecutionError.from_cell_and_msg(cell, exec_reply_content)
nbclient.exceptions.CellExecutionError: An error occurred while executing the following cell:
------------------
#PERFORMING DATA CLEANUP AND OBTAINING A CORRELATION MATRIX

import sqlite3
import pandas as pd
import seaborn as sns
import matplotlib.pyplot as plt
conn = sqlite3.connect('game_database.db')
cursor = conn.cursor()
query = 'SELECT * FROM reviews'
df_reviews = pd.read_sql(query, conn)
print(df_reviews.head())
df_reviews_numeric = df_reviews.drop(columns=['Review'])
correlation_matrix = df_reviews_numeric.corr()
sns.heatmap(correlation_matrix, annot=True, cmap='coolwarm')
plt.title("Correlation Matrix")
plt.show()
conn.close()

------------------


[1;31m---------------------------------------------------------------------------[0m
[1;31mModuleNotFoundError[0m                       Traceback (most recent call last)
Cell [1;32mIn[6], line 5[0m
[0;32m      3[0m [38;5;28;01mimport[39;00m [38;5;21;01msqlite3[39;00m
[0;32m      4[0m [38;5;28;01mimport[39;00m [38;5;21;01mpandas[39;00m [38;5;28;01mas[39;00m [38;5;21;01mpd[39;00m
[1;32m----> 5[0m [38;5;28;01mimport[39;00m [38;5;21;01mseaborn[39;00m [38;5;28;01mas[39;00m [38;5;21;01msns[39;00m
[0;32m      6[0m [38;5;28;01mimport[39;00m [38;5;21;01mmatplotlib[39;00m[38;5;21;01m.[39;00m[38;5;21;01mpyplot[39;00m [38;5;28;01mas[39;00m [38;5;21;01mplt[39;00m
[0;32m      7[0m conn [38;5;241m=[39m sqlite3[38;5;241m.[39mconnect([38;5;124m'[39m[38;5;124mgame_database.db[39m[38;5;124m'[39m)

[1;31mModuleNotFoundError[0m: No module named 'seaborn'

